Workbook

Sheet Summary
A1: Eisla — Financial Summary: Three Scenarios
A2: Same pricing, margins, costs. Only volume differs.
B4: PESSIMISTIC | C4: REALISTIC | D4: OPTIMISTIC
B5: 30% volume | C5: Base plan | D5: ~2x volume
A7: YEAR 1 (2026/27)
A8: Total jobs | B8: ='Pessimistic P&L'!B6 -> 47 | C8: ='Realistic P&L'!B6 -> 155 | D8: ='Optimistic P&L'!B6 -> 280
A9: Revenue | B9: ='Pessimistic P&L'!B20 -> 34166.7 | C9: ='Realistic P&L'!B20 -> 113119 | D9: ='Optimistic P&L'!B20 -> 201599
A10: Gross Profit | B10: ='Pessimistic P&L'!B29 -> 12581.1 | C10: ='Realistic P&L'!B30 -> 41890.215 | D10: ='Optimistic P&L'!B30 -> 150751.02
A11: Fixed Costs | B11: ='Pessimistic P&L'!B42 -> 12500 | C11: ='Realistic P&L'!B40 -> 22000 | D11: ='Optimistic P&L'!B41 -> 121400
A12: Operating Profit | B12: ='Pessimistic P&L'!B44 -> 81.1 | C12: ='Realistic P&L'!B42 -> 19890.215 | D12: ='Optimistic P&L'!B43 -> 29351.015
A13: Operating Margin | B13: ='Pessimistic P&L'!B45 -> 0.0023736562 | C13: ='Realistic P&L'!B43 -> 0.17583443 | D13: ='Optimistic P&L'!B44 -> 0.14559107
A15: YEAR 2 (2027/28)
A16: Total jobs | B16: ='Pessimistic P&L'!C6 -> 180 | C16: ='Realistic P&L'!C6 -> 600 | D16: ='Optimistic P&L'!C6 -> 1100
A17: Revenue | B17: ='Pessimistic P&L'!C20 -> 137553.2 | C17: ='Realistic P&L'!C20 -> 459014 | D17: ='Optimistic P&L'!C20 -> 833428
A18: Gross Profit | B18: ='Pessimistic P&L'!C29 -> 55115.9 | C18: ='Realistic P&L'!C30 -> 349352.79 | D18: ='Optimistic P&L'!C30 -> 631719.58
A19: Fixed Costs | B19: ='Pessimistic P&L'!C42 -> 23900 | C19: ='Realistic P&L'!C40 -> 152700 | D19: ='Optimistic P&L'!C41 -> 291250
A20: Operating Profit | B20: ='Pessimistic P&L'!C44 -> 31215.9 | C20: ='Realistic P&L'!C42 -> 196652.79 | D20: ='Optimistic P&L'!C43 -> 340469.58
A21: Operating Margin | B21: ='Pessimistic P&L'!C45 -> 0.22693692 | C21: ='Realistic P&L'!C43 -> 0.42842438 | D21: ='Optimistic P&L'!C44 -> 0.40851709
A23: YEAR 3 (2028/29)
A24: Total jobs | B24: ='Pessimistic P&L'!D6 -> 540 | C24: ='Realistic P&L'!D6 -> 1800 | D24: ='Optimistic P&L'!D6 -> 3600
A25: Revenue | B25: ='Pessimistic P&L'!D20 -> 419471.6 | C25: ='Realistic P&L'!D20 -> 1398899 | D25: ='Optimistic P&L'!D20 -> 2760993
A26: Gross Profit | B26: ='Pessimistic P&L'!D29 -> 171367.53 | C26: ='Realistic P&L'!D30 -> 1068287.5 | D26: ='Optimistic P&L'!D30 -> 2097696.1
A27: Fixed Costs | B27: ='Pessimistic P&L'!D42 -> 148800 | C27: ='Realistic P&L'!D40 -> 444760 | D27: ='Optimistic P&L'!D41 -> 876360
A28: Operating Profit | B28: ='Pessimistic P&L'!D44 -> 22567.53 | C28: ='Realistic P&L'!D42 -> 623527.52 | D28: ='Optimistic P&L'!D43 -> 1221336.1
A29: Operating Margin | B29: ='Pessimistic P&L'!D45 -> 0.0537999 | C29: ='Realistic P&L'!D43 -> 0.44572733 | D29: ='Optimistic P&L'!D44 -> 0.44235393
A31: 3-YEAR CUMULATIVE
A32: Total Jobs | B32: =B8+B16+B24 -> 767 | C32: =C8+C16+C24 -> 2555 | D32: =D8+D16+D24 -> 4980
A33: Total Revenue | B33: =B9+B17+B25 -> 591191.5 | C33: =C9+C17+C25 -> 1971032 | D33: =D9+D17+D25 -> 3796020
A34: Total Operating Profit | B34: =B12+B20+B28 -> 53864.53 | C34: =C12+C20+C28 -> 840070.52 | D34: =D12+D20+D28 -> 1591156.7
A36: KEY INSIGHT
A37: Profitable in ALL scenarios, ALL years — but pessimistic Y1 is borderline (£281). Marketing at 12% of revenue is the biggest fixed cost driver.
A39: UNIT ECONOMICS (same all scenarios)
A40: Blended design fee | B40: £599
A41: Contract engineer cost/job | B41: £297 (used below breakeven)
A42: Manufacturing margin | B42: 26%
A43: Overall gross margin | B43: 37-42%
A44: FT engineer loaded cost | B44: £86,250/yr + £2,500 setup
A46: ENGINEER STAFFING PLAN
B47: PESSIMISTIC | C47: REALISTIC | D47: OPTIMISTIC
A48: Y1 new design jobs | B48: 44 | C48: 145 | D48: 260
...

Sheet Glossary
A1: Eisla — Glossary of Terms
A2: Technical and financial terms used in this model, for readers without electronics background.
A4: TERM | B4: MEANING
A5: MCU | B5: Microcontroller Unit — the 'brain' chip on a circuit board. A tiny computer that runs device software.
A6: PCB | B6: Printed Circuit Board — the board that electronic components are soldered onto.
A7: PCBA | B7: PCB Assembly — a PCB with all components soldered on, ready to use.
A8: BGA | B8: Ball Grid Array — a chip package with solder balls underneath. Complex to route. Eisla EXCLUDES BGA.
A9: QFN | B9: Quad Flat No-lead — a chip package with pads on bottom edges. Moderate complexity. Supported in Tier 2/3.
A10: LQFP | B10: Low-profile Quad Flat Package — chip with visible legs on all four sides. Common. All tiers.
A11: DIP / SOIC | B11: Through-hole and surface-mount packages with visible pins. Simplest. Tier 1 components.
A12: Gerber files | B12: Industry-standard manufacturing files sent to PCB factories. Like a blueprint for the board.
A13: 4-layer | B13: A PCB with 4 copper layers. Standard for microcontroller projects. All Eisla designs are 4-layer.
A14: ERC / DRC | B14: Electrical / Design Rules Check — automated validation before manufacturing.
A15: FreeRouting | B15: Open-source autorouter software used in Eisla's pipeline to draw copper traces.
A16: KiCad | B16: Open-source PCB design software. Eisla generates KiCad-format designs.
A18: FABRICATION HOUSES
A19: JLCPCB | B19: Chinese PCB fab. Cheapest option. 5-7 day build + 3-5 day shipping to UK. Model base case.
A20: PCBWay | B20: Chinese PCB fab. Similar pricing to JLCPCB.
A21: PCBTrain | B21: UK PCB fab. Higher cost (£280-450 same spec) but faster UK delivery. Same 26% margin applied.
A22: Eurocircuits | B22: European PCB fab. Higher quality/cost. For customers wanting EU supply chain.
A24: FINANCIAL TERMS
A25: Design fee | B25: Customer pays Eisla to convert their description into manufacturable Gerber files.
A26: Mfg margin (26%) | B26: Markup Eisla adds to the fab's cost. This is on manufacturing ONLY, not the design fee.
A27: Overall gross margin (37-42%) | B27: Total revenue minus total variable costs. Higher than 26% because design fee revenue is included.
A28: Blended | B28: Weighted average across tiers. E.g. (25% x T1) + (60% x T2) + (15% x T3).
A29: Variable cost | B29: Costs that scale with each job (engineer, fab, API). More jobs = more cost.
A30: Fixed cost | B30: Costs that stay constant regardless of volume (hosting, insurance, accountancy).
A31: Contribution | B31: Revenue minus variable costs in £. What each job contributes toward fixed costs and profit.
A32: Reorder | B32: Customer ordering another batch of the SAME board. No new design work. Lower margin (13%).
A33: Promotional | B33: Discounted rate (£299 vs £599) for strategic early customers. Capped at 20% Y1, 5% Y2, 0% Y3.
A35: TIERS — automatically assigned by AI based on customer's description
A36: Tier 1 (£499) | B36: Simple: ATmega, STM32F0/F1, ESP8266. Standard packages. No engineer review.
A37: Tier 2 (£599) | B37: Mid: ESP32, RP2040, nRF52840, STM32F4. QFN/LQFP. 4hr engineer review. 60% of jobs.
A38: Tier 3 (£749) | B38: Complex: STM32H7, i.MX RT LQFP176/208. 6hr engineer review. 15% of jobs.
A39: Tier 4 | B39: BGA / application processors. OUT OF SCOPE — referred to specialist. Eisla does not handle BGA.
A41: OTHER
A42: Claude API | B42: Anthropic's AI. Eisla uses it to parse plain-English descriptions into component lists.
A43: DigiKey API | B43: Component distributor API for pricing/availability. Deferred to v2 (£0 in v1).
A44: Stripe | B44: Payment processor. 1.5% + £0.30 per transaction.
A45: Reorder ≠ dissatisfaction | B45: 7% reorder rate means 7% of customers order ADDITIONAL production runs of the same working design.

Sheet Realistic Assumptions
A1: Eisla — Realistic Case: Model Assumptions (v7)
A2: Blue = input | Amber = new/changed in v6 | DigiKey API deferred — £0 in v1. Manufacturing base case: JLCPCB. Customer chooses from JLCPCB / PCBWay / PCBTrain / Eurocircuits at checkout.
A4: PRICING
A5: Design fee — standard blended (£) | B5: 599 | D5: Blended across MCU tiers (see tier reference). T1=£499/T2=£599/T3=£749.
A6: Design fee — promotional (selected customers, £) | B6: 299 | D6: ~50% of standard. Strategic partners only. T2/T3 promo jobs still incur review cost.
A7: Design fee — repeat customer within 6 months (£) | B7: ='Realistic Assumptions'!$B$5*(1-'Realistic Assumptions'!$B$8) -> 539.1 | D7: Auto-calc: standard × (1 − repeat discount). Emailed code, applied at checkout.
A8: Repeat customer discount (%) | B8: 0.1 | D8: 10% off design fee only. Manufacturing always at full price.
A9: Manufacturing margin — prototype (%) | B9: 0.26 | D9: Applied to PCBA landed cost regardless of fab chosen (JLCPCB, PCBWay, PCBTrain, Eurocircuits). Model base case = JLCPCB costs.
A10: Manufacturing margin — reorder (%) | B10: 0.13 | D10: Same board reordered; no design work. Applied regardless of fab chosen.
A11: Promotional mix — Year 1 (% of new design jobs) | B11: 0.2 | D11: 20% Y1 at £299 promo rate.
A12: Promotional mix — Year 2 (% of new design jobs) | B12: 0.05 | D12: 5% Y2; 0% Y3.
A13: Rush surcharge (%) | B13: 0.375 | D13: +37.5% on customer manufacturing price.
A14: Revision fee — 2nd+ revision (£) | B14: 5 | D14: First revision always free.
A16: MCU TIER REFERENCE (no BGA — leaded/QFN only)
A17: Adjust tier fees and mix % to update blended standard fee in B5 and blended review cost in B38.
A18: Tier 1 fee (£) | B18: 499 | D18: ATmega, STM32F0/F1/F3, basic ESP8266. LQFP≤64, DIP, SOIC.
A19: Tier 1 job mix (%) | B19: 0.25 | D19: 25% of jobs
A20: Tier 2 fee (£) | B20: 599 | D20: ESP32, RP2040, nRF52840, STM32F4/F7 LQFP, QFN. Dominant tier.
A21: Tier 2 job mix (%) | B21: 0.6 | D21: 60% of jobs
A22: Tier 3 fee (£) | B22: 749 | D22: STM32H7 LQFP176/208, i.MX RT LQFP. Complex multi-peripheral. No BGA ever.
A23: Tier 3 job mix (%) | B23: 0.15 | D23: 15% of jobs
A24: Blended standard fee — CHECK vs B5 (£) | B24: ='Realistic Assumptions'!$B$18*'Realistic Assumptions'!$B$19+'Realistic Assumptions'!$B$20*'Realistic Assumptions'!$B$21+'Realistic Assumptions'!$B$22*'Realistic Assumptions'!$B$23 -> 596.5 | D24: Should match B5. If tiers change, update B5.
A26: AVERAGE JOB COSTS (variable, per new design job)
A27: Claude API cost per design job (£) | B27: 2 | D27: 3–5 API calls at Sonnet 4 rates | Source: Anthropic API pricing page, Feb 2026. Sonnet 4: ~$3/MTok in, ~$15/MTok out. 3-5 calls/job.
A28: Compute / FreeRouting per job (£) | B28: 1 | D28: Server time for routing + 3D render | Source: Railway.app / Fly.io pricing, Feb 2026. Autoroute + 3D render per job.
A29: DigiKey API lookups per job (£) | B29: 0 | D29: DigiKey API deferred to v2. £0 in v1. | Deferred to v2. DigiKey API is free but integration not built yet.
A30: Average PCBA landed cost — 5 boards (£) | B30: 165 | D30: JLCPCB base case (conservative - most price-sensitive prototype customers). UK fabs (PCBTrain, Eurocircuits) £280-£450 landed for same spec - higher customer price, same 26% margin. Model uses JLCPCB as base; actual mix depends on customer fab choice at checkout. | Source: JLCPCB instant quote tool, Feb 2026. 4-layer, 100x100mm, 5 boards, SMT assembly, DHL shipping.
A31: PCBA landed cost — rush premium (£) | B31: 26 | D31: JLCPCB 48hr uplift base case (~16% of base). UK fabs have different rush structures. | Source: JLCPCB 48-hour rush option. ~16% uplift on base PCBA cost.
A32: Stripe fee rate (%) | B32: 0.015 | D32: 1.5% per transaction | Source: Stripe UK pricing page, Feb 2026. Standard rate for UK cards.
A33: Stripe fixed fee per transaction (£) | B33: 0.3 | D33: £0.30 per charge
A34: ENGINEER DESIGN REVIEW (variable cost — T2 and T3 only)
A35: T1 designs: no review (simple, automated output sufficient). T2/T3: mandatory review before Gerbers released to fab.
A36: Engineer hourly rate (£) | B36: 90 | D36: Contract electronics engineer. Day rate ~£720. | Source: Contract electronics engineer market rate, UK. Verified via PeoplePerHour/Upwork, Feb 2026. Day rate £600-£800, midpoint £720.
A37: Tier 1 review hours | B37: 0 | D37: No review — simple routing, single supply, standard packages
A38: Tier 2 review hours | B38: 4 | D38: 4 hours — ESP32/RP2040/nRF52840/STM32F4 complexity | Estimate: ESP32/RP2040 schematic + layout review. To be validated with engineer before launch.
A39: Tier 3 review hours | B39: 6 | D39: 6 hours — STM32H7/i.MX RT, complex multi-peripheral | Estimate: STM32H7/i.MX RT multi-peripheral review. To be validated with engineer before launch.
A40: Tier 1 review cost (£) | B40: ='Realistic Assumptions'!$B$37*'Realistic Assumptions'!$B$36 -> 0 | D40: Auto-calc: T1 hours × rate
A41: Tier 2 review cost (£) | B41: ='Realistic Assumptions'!$B$38*'Realistic Assumptions'!$B$36 -> 360 | D41: Auto-calc: 4h × £90 = £360
A42: Tier 3 review cost (£) | B42: ='Realistic Assumptions'!$B$39*'Realistic Assumptions'!$B$36 -> 540 | D42: Auto-calc: 6h × £90 = £540
A43: Blended review cost per new design job (£) | B43: ='Realistic Assumptions'!$B$19*'Realistic Assumptions'!$B$40+'Realistic Assumptions'!$B$21*'Realistic Assumptions'!$B$41+'Realistic Assumptions'!$B$23*'Realistic Assumptions'!$B$42 -> 297 | D43: Weighted: 25%×£0 + 60%×£360 + 15%×£540 = £297. Applies to standard, repeat, AND promotional new design jobs.
...

Sheet Unit Economics
A1: Eisla — Unit Economics (all 4-layer, no BGA, incl. engineer review | Mfg base case: JLCPCB; 26% manufacturing margin applied to all fabs)
B3: Standard £599 blended | C3: Promotional £299 | D3: Repeat <6m £539 blended | E3: Rush +37.5% mfg | F3: Reorder (no design) | G3: Notes
A4: REVENUE
A5: Design fee | B5: ='Realistic Assumptions'!$B$5 -> 599 | C5: ='Realistic Assumptions'!$B$6 -> 299 | D5: ='Realistic Assumptions'!$B$7 -> 539.1 | E5: ='Realistic Assumptions'!$B$5 -> 599 | F5: =0 -> 0 | G5: Blended fee = 25%×£499 + 60%×£599 + 15%×£749. Repeat = standard × 90%.
A6: Manufacturing revenue (customer price) | B6: =ROUND('Realistic Assumptions'!$B$30/(1-'Realistic Assumptions'!$B$9),0) -> 223 | C6: =ROUND('Realistic Assumptions'!$B$30/(1-'Realistic Assumptions'!$B$9),0) -> 223 | D6: =ROUND('Realistic Assumptions'!$B$30/(1-'Realistic Assumptions'!$B$9),0) -> 223 | E6: =ROUND(('Realistic Assumptions'!$B$30+'Realistic Assumptions'!$B$31)/(1-'Realistic Assumptions'!$B$9)*(1+'Realistic Assumptions'!$B$13),0) -> 355 | F6: =ROUND('Realistic Assumptions'!$B$30/(1-'Realistic Assumptions'!$B$10),0) -> 190 | G6: Mfg revenue same formula regardless of fab customer chooses. Base case = JLCPCB £165 landed. UK fabs higher absolute revenue at same 26% margin. Model is conservative.
A7: Total Revenue per Job | B7: =B5+B6 -> 822 | C7: =C5+C6 -> 522 | D7: =D5+D6 -> 762.1 | E7: =E5+E6 -> 954 | F7: =F5+F6 -> 190
A9: VARIABLE COSTS
A10: PCBA landed cost | B10: ='Realistic Assumptions'!$B$30 -> 165 | C10: ='Realistic Assumptions'!$B$30 -> 165 | D10: ='Realistic Assumptions'!$B$30 -> 165 | E10: ='Realistic Assumptions'!$B$30+'Realistic Assumptions'!$B$31 -> 191 | F10: ='Realistic Assumptions'!$B$30 -> 165 | G10: 4-layer £140–£200, midpoint £165. Rush adds £26.
A11: Engineer design review | B11: ='Realistic Assumptions'!$B$43 -> 297 | C11: ='Realistic Assumptions'!$B$43 -> 297 | D11: ='Realistic Assumptions'!$B$43 -> 297 | E11: ='Realistic Assumptions'!$B$43 -> 297 | F11: =0 -> 0 | G11: T1=£0, T2=£360, T3=£540. Blended £297. Applies to ALL new design jobs incl. promo/repeat.
A12: Claude API | B12: ='Realistic Assumptions'!$B$27 -> 2 | C12: ='Realistic Assumptions'!$B$27 -> 2 | D12: ='Realistic Assumptions'!$B$27 -> 2 | E12: ='Realistic Assumptions'!$B$27 -> 2 | F12: =0 -> 0
A13: Compute / FreeRouting | B13: ='Realistic Assumptions'!$B$28 -> 1 | C13: ='Realistic Assumptions'!$B$28 -> 1 | D13: ='Realistic Assumptions'!$B$28 -> 1 | E13: ='Realistic Assumptions'!$B$28 -> 1 | F13: =0 -> 0
A14: DigiKey API | B14: ='Realistic Assumptions'!$B$29 -> 0 | C14: ='Realistic Assumptions'!$B$29 -> 0 | D14: ='Realistic Assumptions'!$B$29 -> 0 | E14: ='Realistic Assumptions'!$B$29 -> 0 | F14: =0 -> 0
A15: Stripe processing fees | B15: =B7*'Realistic Assumptions'!$B$32+'Realistic Assumptions'!$B$33*2 -> 12.93 | C15: =C7*'Realistic Assumptions'!$B$32+'Realistic Assumptions'!$B$33*2 -> 8.43 | D15: =D7*'Realistic Assumptions'!$B$32+'Realistic Assumptions'!$B$33*2 -> 12.0315 | E15: =E7*'Realistic Assumptions'!$B$32+'Realistic Assumptions'!$B$33*2 -> 14.91 | F15: =F7*'Realistic Assumptions'!$B$32+'Realistic Assumptions'!$B$33*1 -> 3.15
A16: Total Variable Cost | B16: =SUM(B10:B15) -> 477.93 | C16: =SUM(C10:C15) -> 473.43 | D16: =SUM(D10:D15) -> 477.0315 | E16: =SUM(E10:E15) -> 505.91 | F16: =SUM(F10:F15) -> 168.15
A18: CONTRIBUTION
A19: Gross Profit per Job | B19: =B7-B16 -> 344.07 | C19: =C7-C16 -> 48.57 | D19: =D7-D16 -> 285.0685 | E19: =E7-E16 -> 448.09 | F19: =F7-F16 -> 21.85
A20: Gross Margin % | B20: =IFERROR(B19/B7,0) -> 0.41857664 | C20: =IFERROR(C19/C7,0) -> 0.093045977 | D20: =IFERROR(D19/D7,0) -> 0.37405655 | E20: =IFERROR(E19/E7,0) -> 0.46969602 | F20: =IFERROR(F19/F7,0) -> 0.115
A22: MCU TIER BREAKDOWN & REVIEW COSTS | C22: Design Fee | D22: Review Cost
A23: Tier 1 (25%): ATmega, STM32F0/F1/F3, ESP8266 | C23: 499 | D23: 0 | E23: LQFP≤64, DIP — no review required
A24: Tier 2 (60%): ESP32, RP2040, nRF52840, STM32F4 | C24: 599 | D24: 360 | E24: QFN/LQFP — 4h engineer review @ £90/hr
A25: Tier 3 (15%): STM32H7, i.MX RT in LQFP | C25: 749 | D25: 540 | E25: LQFP176/208 — 6h engineer review @ £90/hr
A26: Tier 4: BGA / application processor | C26: — | D26: — | E26: Out of scope — refer to specialist engineer
A28: Note: Blended review cost = 25%×£0 + 60%×£360 + 15%×£540 = £297. Applied to ALL new design jobs regardless of pricing tier. Reorders have no review cost. Module add-ons sit on top of tier fee — model uses blended tier as conservative base.
A30: MARGIN CLARIFICATION
A31: 26% manufacturing margin = markup on PCBA cost ONLY (£165 → £223). This is the margin on the manufacturing portion of the order.
A32: 37-42% overall gross margin = total revenue (design fee + manufacturing) minus all variable costs. Higher because design fees are mostly margin.
A33: These are two different metrics measuring different things. Both are correct.

Sheet Pessimistic P&L
A1: Eisla — Pessimistic Case: 3-Year P&L (30% of Realistic)
A2: Stress test: what if growth is 70% slower than planned? All pricing, costs, and margins identical to base case.
B3: Year 1 2026/27 | C3: Year 2 2027/28 | D3: Year 3 2028/29 | E3: vs Base Year 1 | F3: vs Base Year 3
A5: VOLUME
A6: Total jobs | B6: 47 | C6: 180 | D6: 540
A7: New design jobs | B7: 44 | C7: 167 | D7: 502
A8: of which: standard (£599) | B8: 28 | C8: 117 | D8: 326
A9: of which: promotional (£299) | B9: 9 | C9: 8 | D9: 0
A10: of which: repeat customer (£539) | B10: 7 | C10: 42 | D10: 176
A11: Rush jobs | B11: 4 | C11: 20 | D11: 75
A12: Reorder jobs | B12: 3 | C12: 13 | D12: 38
A14: REVENUE (£)
A15: Design fee revenue | B15: 23236.7 | C15: 95117.2 | D15: 290155.6
A16: Manufacturing — standard | B16: 9812 | C16: 37241 | D16: 111946
A17: Manufacturing — rush | B17: 528 | C17: 2640 | D17: 9900
A18: Reorder revenue | B18: 570 | C18: 2470 | D18: 7220
A19: Revision fees | B19: 20 | C19: 85 | D19: 250
A20: Total Revenue | B20: 34166.7 | C20: 137553.2 | D20: 419471.6
A22: VARIABLE COSTS (£)
A23: PCBA cost | B23: 7859 | C23: 30220 | D23: 91050
A24: Engineer design review | B24: 13068 | C24: 49599 | D24: 0
A25: Claude API | B25: 88 | C25: 334 | D25: 1004
A26: Compute / routing | B26: 44 | C26: 167 | D26: 502
A27: Stripe fees | B27: 526.6 | C27: 2117.3 | D27: 6454.07
A28: Total Variable Costs | B28: 21585.6 | C28: 82437.3 | D28: 248104.07
A29: Gross Profit | B29: 12581.1 | C29: 55115.9 | D29: 171367.53
A30: Gross Margin % | B30: 0.3682 | C30: 0.4007 | D30: 0.4085
A32: FIXED COSTS (£)
A33: Hosting | B33: 1800 | C33: 2400 | D33: 3600
A34: Domain, IT & data | B34: 1160 | C34: 1260 | D34: 1510
A35: Accountancy & legal | B35: 3300 | C35: 1500 | D35: 2000
A36: Insurance (PI) | B36: 500 | C36: 500 | D36: 700
A37: Marketing (12% of revenue) | B37: 4000 | C37: 16500 | D37: 50500
A38: Home office / premises | B38: 1200 | C38: 1200 | D38: 1200
A39: Broadband | B39: 360 | C39: 360 | D39: 360
A40: Phone / comms | B40: 180 | C40: 180 | D40: 180
A41: Full-time engineers (loaded cost) | B41: 0 | C41: 0 | D41: 88750
A42: Total Fixed Costs | B42: =SUM(B33:B41) -> 12500 | C42: =SUM(C33:C41) -> 23900 | D42: =SUM(D33:D41) -> 148800
A44: Operating Profit | B44: =B29-B42 -> 81.1 | C44: =C29-C42 -> 31215.9 | D44: =D29-D42 -> 22567.53
A45: Operating Margin % | B45: =IFERROR(B44/B20,0) -> 0.0023736562 | C45: =IFERROR(C44/C20,0) -> 0.22693692 | D45: =IFERROR(D44/D20,0) -> 0.0537999
...

Sheet Realistic Y1 Monthly
A1: Eisla — Realistic Case: Year 1 Monthly P&L (Apr 2026 – Mar 2027)
B3: Apr | C3: May | D3: Jun | E3: Jul | F3: Aug | G3: Sep | H3: Oct | I3: Nov | J3: Dec | K3: Jan | L3: Feb | M3: Mar | O3: FY Total
A4: JOB VOLUMES
A5: Total jobs in month | B5: 3 | C5: 4 | D5: 4 | E5: 7 | F5: 10 | G5: 12 | H5: 14 | I5: 17 | J5: 18 | K5: 20 | L5: 22 | M5: 24 | O5: =SUM(B5:M5) -> 155
A6: Reorder jobs (same board) | B6: =ROUND(B5*'Realistic Assumptions'!$B$49,0) -> 0 | C6: =ROUND(C5*'Realistic Assumptions'!$B$49,0) -> 0 | D6: =ROUND(D5*'Realistic Assumptions'!$B$49,0) -> 0 | E6: =ROUND(E5*'Realistic Assumptions'!$B$49,0) -> 0 | F6: =ROUND(F5*'Realistic Assumptions'!$B$49,0) -> 1 | G6: =ROUND(G5*'Realistic Assumptions'!$B$49,0) -> 1 | H6: =ROUND(H5*'Realistic Assumptions'!$B$49,0) -> 1 | I6: =ROUND(I5*'Realistic Assumptions'!$B$49,0) -> 1 | ... M6: =ROUND(M5*'Realistic Assumptions'!$B$49,0) -> 2 | O6: =SUM(B6:M6) -> 10
A7: New design jobs | B7: =B5-B6 -> 3 | C7: =C5-C6 -> 4 | D7: =D5-D6 -> 4 | E7: =E5-E6 -> 7 | F7: =F5-F6 -> 9 | G7: =G5-G6 -> 11 | H7: =H5-H6 -> 13 | I7: =I5-I6 -> 16 | ... M7: =M5-M6 -> 22 | O7: =SUM(B7:M7) -> 145
A8: Rush jobs | B8: =ROUND(B7*0,0) -> 0 | C8: =ROUND(C7*0,0) -> 0 | D8: =ROUND(D7*0.05,0) -> 0 | E8: =ROUND(E7*0.05,0) -> 0 | F8: =ROUND(F7*0.08,0) -> 1 | G8: =ROUND(G7*0.08,0) -> 1 | H8: =ROUND(H7*0.1,0) -> 1 | I8: =ROUND(I7*0.1,0) -> 2 | J8: =ROUND(J7*0.1,0) -> 2 | K8: =ROUND(K7*0.12,0) -> 2 | L8: =ROUND(L7*0.12,0) -> 2 | M8: =ROUND(M7*0.12,0) -> 3 | O8: =SUM(B8:M8) -> 14
A9: Promotional rate jobs (£299) | B9: =ROUND(B7*'Realistic Assumptions'!$B$11,0) -> 1 | C9: =ROUND(C7*'Realistic Assumptions'!$B$11,0) -> 1 | D9: =ROUND(D7*'Realistic Assumptions'!$B$11,0) -> 1 | E9: =ROUND(E7*'Realistic Assumptions'!$B$11,0) -> 1 | F9: =ROUND(F7*'Realistic Assumptions'!$B$11,0) -> 2 | G9: =ROUND(G7*'Realistic Assumptions'!$B$11,0) -> 2 | H9: =ROUND(H7*'Realistic Assumptions'!$B$11,0) -> 3 | I9: =ROUND(I7*'Realistic Assumptions'!$B$11,0) -> 3 | ... M9: =ROUND(M7*'Realistic Assumptions'!$B$11,0) -> 4 | O9: =SUM(B9:M9) -> 29
A10: Repeat customer jobs (£539 blended) | B10: =ROUND(B7*0,0) -> 0 | C10: =ROUND(C7*0,0) -> 0 | D10: =ROUND(D7*0,0) -> 0 | E10: =ROUND(E7*0.05,0) -> 0 | F10: =ROUND(F7*0.08,0) -> 1 | G10: =ROUND(G7*0.1,0) -> 1 | H10: =ROUND(H7*0.12,0) -> 2 | I10: =ROUND(I7*0.15,0) -> 2 | J10: =ROUND(J7*0.18,0) -> 3 | K10: =ROUND(K7*0.18,0) -> 3 | L10: =ROUND(L7*0.2,0) -> 4 | M10: =ROUND(M7*0.2,0) -> 4 | O10: =SUM(B10:M10) -> 20
A11: Standard rate jobs (£599 blended) | B11: =B7-B9-B10 -> 2 | C11: =C7-C9-C10 -> 3 | D11: =D7-D9-D10 -> 3 | E11: =E7-E9-E10 -> 6 | F11: =F7-F9-F10 -> 6 | G11: =G7-G9-G10 -> 8 | H11: =H7-H9-H10 -> 8 | I11: =I7-I9-I10 -> 11 | ... M11: =M7-M9-M10 -> 14 | O11: =SUM(B11:M11) -> 96
A13: REVENUE (£)
A14: Design fee revenue | B14: =B9*'Realistic Assumptions'!$B$6+B10*'Realistic Assumptions'!$B$7+B11*'Realistic Assumptions'!$B$5 -> 1497 | C14: =C9*'Realistic Assumptions'!$B$6+C10*'Realistic Assumptions'!$B$7+C11*'Realistic Assumptions'!$B$5 -> 2096 | D14: =D9*'Realistic Assumptions'!$B$6+D10*'Realistic Assumptions'!$B$7+D11*'Realistic Assumptions'!$B$5 -> 2096 | E14: =E9*'Realistic Assumptions'!$B$6+E10*'Realistic Assumptions'!$B$7+E11*'Realistic Assumptions'!$B$5 -> 3893 | F14: =F9*'Realistic Assumptions'!$B$6+F10*'Realistic Assumptions'!$B$7+F11*'Realistic Assumptions'!$B$5 -> 4731.1 | G14: =G9*'Realistic Assumptions'!$B$6+G10*'Realistic Assumptions'!$B$7+G11*'Realistic Assumptions'!$B$5 -> 5929.1 | H14: =H9*'Realistic Assumptions'!$B$6+H10*'Realistic Assumptions'!$B$7+H11*'Realistic Assumptions'!$B$5 -> 6767.2 | I14: =I9*'Realistic Assumptions'!$B$6+I10*'Realistic Assumptions'!$B$7+I11*'Realistic Assumptions'!$B$5 -> 8564.2 | ... M14: =M9*'Realistic Assumptions'!$B$6+M10*'Realistic Assumptions'!$B$7+M11*'Realistic Assumptions'!$B$5 -> 11738.4 | O14: =SUM(B14:M14) -> 76957
A15: Manufacturing revenue — standard | B15: =(B7-B8)*ROUND('Realistic Assumptions'!$B$30/(1-'Realistic Assumptions'!$B$9),0) -> 669 | C15: =(C7-C8)*ROUND('Realistic Assumptions'!$B$30/(1-'Realistic Assumptions'!$B$9),0) -> 892 | D15: =(D7-D8)*ROUND('Realistic Assumptions'!$B$30/(1-'Realistic Assumptions'!$B$9),0) -> 892 | E15: =(E7-E8)*ROUND('Realistic Assumptions'!$B$30/(1-'Realistic Assumptions'!$B$9),0) -> 1561 | F15: =(F7-F8)*ROUND('Realistic Assumptions'!$B$30/(1-'Realistic Assumptions'!$B$9),0) -> 1784 | G15: =(G7-G8)*ROUND('Realistic Assumptions'!$B$30/(1-'Realistic Assumptions'!$B$9),0) -> 2230 | H15: =(H7-H8)*ROUND('Realistic Assumptions'!$B$30/(1-'Realistic Assumptions'!$B$9),0) -> 2676 | I15: =(I7-I8)*ROUND('Realistic Assumptions'!$B$30/(1-'Realistic Assumptions'!$B$9),0) -> 3122 | ... M15: =(M7-M8)*ROUND('Realistic Assumptions'!$B$30/(1-'Realistic Assumptions'!$B$9),0) -> 4237 | O15: =SUM(B15:M15) -> 29213
A16: Manufacturing revenue — rush | B16: =B8*ROUND(('Realistic Assumptions'!$B$30+'Realistic Assumptions'!$B$31)/(1-'Realistic Assumptions'!$B$9)*(1+'Realistic Assumptions'!$B$13),0) -> 0 | C16: =C8*ROUND(('Realistic Assumptions'!$B$30+'Realistic Assumptions'!$B$31)/(1-'Realistic Assumptions'!$B$9)*(1+'Realistic Assumptions'!$B$13),0) -> 0 | D16: =D8*ROUND(('Realistic Assumptions'!$B$30+'Realistic Assumptions'!$B$31)/(1-'Realistic Assumptions'!$B$9)*(1+'Realistic Assumptions'!$B$13),0) -> 0 | E16: =E8*ROUND(('Realistic Assumptions'!$B$30+'Realistic Assumptions'!$B$31)/(1-'Realistic Assumptions'!$B$9)*(1+'Realistic Assumptions'!$B$13),0) -> 0 | F16: =F8*ROUND(('Realistic Assumptions'!$B$30+'Realistic Assumptions'!$B$31)/(1-'Realistic Assumptions'!$B$9)*(1+'Realistic Assumptions'!$B$13),0) -> 355 | G16: =G8*ROUND(('Realistic Assumptions'!$B$30+'Realistic Assumptions'!$B$31)/(1-'Realistic Assumptions'!$B$9)*(1+'Realistic Assumptions'!$B$13),0) -> 355 | H16: =H8*ROUND(('Realistic Assumptions'!$B$30+'Realistic Assumptions'!$B$31)/(1-'Realistic Assumptions'!$B$9)*(1+'Realistic Assumptions'!$B$13),0) -> 355 | I16: =I8*ROUND(('Realistic Assumptions'!$B$30+'Realistic Assumptions'!$B$31)/(1-'Realistic Assumptions'!$B$9)*(1+'Realistic Assumptions'!$B$13),0) -> 710 | ... M16: =M8*ROUND(('Realistic Assumptions'!$B$30+'Realistic Assumptions'!$B$31)/(1-'Realistic Assumptions'!$B$9)*(1+'Realistic Assumptions'!$B$13),0) -> 1065 | O16: =SUM(B16:M16) -> 4970
A17: Reorder revenue | B17: =B6*ROUND('Realistic Assumptions'!$B$30/(1-'Realistic Assumptions'!$B$10),0) -> 0 | C17: =C6*ROUND('Realistic Assumptions'!$B$30/(1-'Realistic Assumptions'!$B$10),0) -> 0 | D17: =D6*ROUND('Realistic Assumptions'!$B$30/(1-'Realistic Assumptions'!$B$10),0) -> 0 | E17: =E6*ROUND('Realistic Assumptions'!$B$30/(1-'Realistic Assumptions'!$B$10),0) -> 0 | F17: =F6*ROUND('Realistic Assumptions'!$B$30/(1-'Realistic Assumptions'!$B$10),0) -> 190 | G17: =G6*ROUND('Realistic Assumptions'!$B$30/(1-'Realistic Assumptions'!$B$10),0) -> 190 | H17: =H6*ROUND('Realistic Assumptions'!$B$30/(1-'Realistic Assumptions'!$B$10),0) -> 190 | I17: =I6*ROUND('Realistic Assumptions'!$B$30/(1-'Realistic Assumptions'!$B$10),0) -> 190 | ... M17: =M6*ROUND('Realistic Assumptions'!$B$30/(1-'Realistic Assumptions'!$B$10),0) -> 380 | O17: =SUM(B17:M17) -> 1900
A18: Revision fees | B18: =ROUND(B5*'Realistic Assumptions'!$B$58*'Realistic Assumptions'!$B$14,0) -> 2 | C18: =ROUND(C5*'Realistic Assumptions'!$B$58*'Realistic Assumptions'!$B$14,0) -> 2 | D18: =ROUND(D5*'Realistic Assumptions'!$B$58*'Realistic Assumptions'!$B$14,0) -> 2 | E18: =ROUND(E5*'Realistic Assumptions'!$B$58*'Realistic Assumptions'!$B$14,0) -> 4 | F18: =ROUND(F5*'Realistic Assumptions'!$B$58*'Realistic Assumptions'!$B$14,0) -> 5 | G18: =ROUND(G5*'Realistic Assumptions'!$B$58*'Realistic Assumptions'!$B$14,0) -> 6 | H18: =ROUND(H5*'Realistic Assumptions'!$B$58*'Realistic Assumptions'!$B$14,0) -> 7 | I18: =ROUND(I5*'Realistic Assumptions'!$B$58*'Realistic Assumptions'!$B$14,0) -> 9 | ... M18: =ROUND(M5*'Realistic Assumptions'!$B$58*'Realistic Assumptions'!$B$14,0) -> 12 | O18: =SUM(B18:M18) -> 79
A19: Total Revenue | B19: =SUM(B14:B18) -> 2168 | C19: =SUM(C14:C18) -> 2990 | D19: =SUM(D14:D18) -> 2990 | E19: =SUM(E14:E18) -> 5458 | F19: =SUM(F14:F18) -> 7065.1 | G19: =SUM(G14:G18) -> 8710.1 | H19: =SUM(H14:H18) -> 9995.2 | I19: =SUM(I14:I18) -> 12595.2 | ... M19: =SUM(M14:M18) -> 17432.4 | O19: =SUM(B19:M19) -> 113119
A21: VARIABLE COSTS (£)
A22: PCBA cost (paid to JLCPCB) | B22: =B5*'Realistic Assumptions'!$B$30+B8*'Realistic Assumptions'!$B$31 -> 495 | C22: =C5*'Realistic Assumptions'!$B$30+C8*'Realistic Assumptions'!$B$31 -> 660 | D22: =D5*'Realistic Assumptions'!$B$30+D8*'Realistic Assumptions'!$B$31 -> 660 | E22: =E5*'Realistic Assumptions'!$B$30+E8*'Realistic Assumptions'!$B$31 -> 1155 | F22: =F5*'Realistic Assumptions'!$B$30+F8*'Realistic Assumptions'!$B$31 -> 1676 | G22: =G5*'Realistic Assumptions'!$B$30+G8*'Realistic Assumptions'!$B$31 -> 2006 | H22: =H5*'Realistic Assumptions'!$B$30+H8*'Realistic Assumptions'!$B$31 -> 2336 | I22: =I5*'Realistic Assumptions'!$B$30+I8*'Realistic Assumptions'!$B$31 -> 2857 | ... M22: =M5*'Realistic Assumptions'!$B$30+M8*'Realistic Assumptions'!$B$31 -> 4038 | O22: =SUM(B22:M22) -> 25939
A23: Engineer design review | B23: =B7*'Realistic Assumptions'!$B$43 -> 891 | C23: =C7*'Realistic Assumptions'!$B$43 -> 1188 | D23: =D7*'Realistic Assumptions'!$B$43 -> 1188 | E23: =E7*'Realistic Assumptions'!$B$43 -> 2079 | F23: =F7*'Realistic Assumptions'!$B$43 -> 2673 | G23: =G7*'Realistic Assumptions'!$B$43 -> 3267 | H23: =H7*'Realistic Assumptions'!$B$43 -> 3861 | I23: =I7*'Realistic Assumptions'!$B$43 -> 4752 | ... M23: =M7*'Realistic Assumptions'!$B$43 -> 6534 | O23: =SUM(B23:M23) -> 43065
A24: Claude API | B24: =B7*'Realistic Assumptions'!$B$27 -> 6 | C24: =C7*'Realistic Assumptions'!$B$27 -> 8 | D24: =D7*'Realistic Assumptions'!$B$27 -> 8 | E24: =E7*'Realistic Assumptions'!$B$27 -> 14 | F24: =F7*'Realistic Assumptions'!$B$27 -> 18 | G24: =G7*'Realistic Assumptions'!$B$27 -> 22 | H24: =H7*'Realistic Assumptions'!$B$27 -> 26 | I24: =I7*'Realistic Assumptions'!$B$27 -> 32 | ... M24: =M7*'Realistic Assumptions'!$B$27 -> 44 | O24: =SUM(B24:M24) -> 290
A25: Compute / routing | B25: =B7*'Realistic Assumptions'!$B$28 -> 3 | C25: =C7*'Realistic Assumptions'!$B$28 -> 4 | D25: =D7*'Realistic Assumptions'!$B$28 -> 4 | E25: =E7*'Realistic Assumptions'!$B$28 -> 7 | F25: =F7*'Realistic Assumptions'!$B$28 -> 9 | G25: =G7*'Realistic Assumptions'!$B$28 -> 11 | H25: =H7*'Realistic Assumptions'!$B$28 -> 13 | I25: =I7*'Realistic Assumptions'!$B$28 -> 16 | ... M25: =M7*'Realistic Assumptions'!$B$28 -> 22 | O25: =SUM(B25:M25) -> 145
A26: DigiKey API | B26: =B7*'Realistic Assumptions'!$B$29 -> 0 | C26: =C7*'Realistic Assumptions'!$B$29 -> 0 | D26: =D7*'Realistic Assumptions'!$B$29 -> 0 | E26: =E7*'Realistic Assumptions'!$B$29 -> 0 | F26: =F7*'Realistic Assumptions'!$B$29 -> 0 | G26: =G7*'Realistic Assumptions'!$B$29 -> 0 | H26: =H7*'Realistic Assumptions'!$B$29 -> 0 | I26: =I7*'Realistic Assumptions'!$B$29 -> 0 | ... M26: =M7*'Realistic Assumptions'!$B$29 -> 0 | O26: =SUM(B26:M26) -> 0
A27: Stripe fees | B27: =B19*'Realistic Assumptions'!$B$32+B5*2*'Realistic Assumptions'!$B$33 -> 34.32 | C27: =C19*'Realistic Assumptions'!$B$32+C5*2*'Realistic Assumptions'!$B$33 -> 47.25 | D27: =D19*'Realistic Assumptions'!$B$32+D5*2*'Realistic Assumptions'!$B$33 -> 47.25 | E27: =E19*'Realistic Assumptions'!$B$32+E5*2*'Realistic Assumptions'!$B$33 -> 86.07 | F27: =F19*'Realistic Assumptions'!$B$32+F5*2*'Realistic Assumptions'!$B$33 -> 111.9765 | G27: =G19*'Realistic Assumptions'!$B$32+G5*2*'Realistic Assumptions'!$B$33 -> 137.8515 | H27: =H19*'Realistic Assumptions'!$B$32+H5*2*'Realistic Assumptions'!$B$33 -> 158.328 | I27: =I19*'Realistic Assumptions'!$B$32+I5*2*'Realistic Assumptions'!$B$33 -> 199.128 | ... M27: =M19*'Realistic Assumptions'!$B$32+M5*2*'Realistic Assumptions'!$B$33 -> 275.886 | O27: =SUM(B27:M27) -> 1789.785
A28: Total Variable Costs | B28: =SUM(B22:B27) -> 1429.32 | C28: =SUM(C22:C27) -> 1907.25 | D28: =SUM(D22:D27) -> 1907.25 | E28: =SUM(E22:E27) -> 3341.07 | F28: =SUM(F22:F27) -> 4487.9765 | G28: =SUM(G22:G27) -> 5443.8515 | H28: =SUM(H22:H27) -> 6394.328 | I28: =SUM(I22:I27) -> 7856.128 | ... M28: =SUM(M22:M27) -> 10913.886 | O28: =SUM(B28:M28) -> 71228.785
A29: Gross Profit | B29: =B19-B28 -> 738.68 | C29: =C19-C28 -> 1082.75 | D29: =D19-D28 -> 1082.75 | E29: =E19-E28 -> 2116.93 | F29: =F19-F28 -> 2577.1235 | G29: =G19-G28 -> 3266.2485 | H29: =H19-H28 -> 3600.872 | I29: =I19-I28 -> 4739.072 | ... M29: =M19-M28 -> 6518.514 | O29: =SUM(B29:M29) -> 41890.215
A30: Gross Margin % | B30: =IFERROR(B29/B19,0) -> 0.34071956 | C30: =IFERROR(C29/C19,0) -> 0.36212375 | D30: =IFERROR(D29/D19,0) -> 0.36212375 | E30: =IFERROR(E29/E19,0) -> 0.38785819 | F30: =IFERROR(F29/F19,0) -> 0.36476816 | G30: =IFERROR(G29/G19,0) -> 0.37499552 | H30: =IFERROR(H29/H19,0) -> 0.36026012 | I30: =IFERROR(I29/I19,0) -> 0.37626016 | ... M30: =IFERROR(M29/M19,0) -> 0.37393096 | O30: =SUM(B30:M30) -> 4.4133845
A32: FIXED COSTS (£)
A33: Hosting | B33: =ROUND('Realistic Assumptions'!$B$61/12,0) -> 150 | C33: =ROUND('Realistic Assumptions'!$B$61/12,0) -> 150 | D33: =ROUND('Realistic Assumptions'!$B$61/12,0) -> 150 | E33: =ROUND('Realistic Assumptions'!$B$61/12,0) -> 150 | F33: =ROUND('Realistic Assumptions'!$B$61/12,0) -> 150 | G33: =ROUND('Realistic Assumptions'!$B$61/12,0) -> 150 | H33: =ROUND('Realistic Assumptions'!$B$61/12,0) -> 150 | I33: =ROUND('Realistic Assumptions'!$B$61/12,0) -> 150 | ... M33: =ROUND('Realistic Assumptions'!$B$61/12,0) -> 150 | O33: =SUM(B33:M33) -> 1800
A34: Domain, IT & data | B34: 97 | C34: 97 | D34: 97 | E34: 97 | F34: 97 | G34: 97 | H34: 97 | I34: 97 | J34: 97 | K34: 97 | L34: 97 | M34: 97 | O34: =SUM(B34:M34) -> 1164
A35: Accountancy & legal | B35: =ROUND('Realistic Assumptions'!$B$66/12,0) -> 275 | C35: =ROUND('Realistic Assumptions'!$B$66/12,0) -> 275 | D35: =ROUND('Realistic Assumptions'!$B$66/12,0) -> 275 | E35: =ROUND('Realistic Assumptions'!$B$66/12,0) -> 275 | F35: =ROUND('Realistic Assumptions'!$B$66/12,0) -> 275 | G35: =ROUND('Realistic Assumptions'!$B$66/12,0) -> 275 | H35: =ROUND('Realistic Assumptions'!$B$66/12,0) -> 275 | I35: =ROUND('Realistic Assumptions'!$B$66/12,0) -> 275 | ... M35: =ROUND('Realistic Assumptions'!$B$66/12,0) -> 275 | O35: =SUM(B35:M35) -> 3300
A36: Insurance (PI) | B36: =ROUND('Realistic Assumptions'!$B$67/12,0) -> 42 | C36: =ROUND('Realistic Assumptions'!$B$67/12,0) -> 42 | D36: =ROUND('Realistic Assumptions'!$B$67/12,0) -> 42 | E36: =ROUND('Realistic Assumptions'!$B$67/12,0) -> 42 | F36: =ROUND('Realistic Assumptions'!$B$67/12,0) -> 42 | G36: =ROUND('Realistic Assumptions'!$B$67/12,0) -> 42 | H36: =ROUND('Realistic Assumptions'!$B$67/12,0) -> 42 | I36: =ROUND('Realistic Assumptions'!$B$67/12,0) -> 42 | ... M36: =ROUND('Realistic Assumptions'!$B$67/12,0) -> 42 | O36: =SUM(B36:M36) -> 504
A37: Marketing (12% of revenue) | B37: 1125 | C37: 1125 | D37: 1125 | E37: 1125 | F37: 1125 | G37: 1125 | H37: 1125 | I37: 1125 | J37: 1125 | K37: 1125 | L37: 1125 | M37: 1125 | O37: =SUM(B37:M37) -> 13500
A38: Home office | B38: =ROUND('Realistic Assumptions'!$B$71/12,0) -> 145 | C38: =ROUND('Realistic Assumptions'!$B$71/12,0) -> 145 | D38: =ROUND('Realistic Assumptions'!$B$71/12,0) -> 145 | E38: =ROUND('Realistic Assumptions'!$B$71/12,0) -> 145 | F38: =ROUND('Realistic Assumptions'!$B$71/12,0) -> 145 | G38: =ROUND('Realistic Assumptions'!$B$71/12,0) -> 145 | H38: =ROUND('Realistic Assumptions'!$B$71/12,0) -> 145 | I38: =ROUND('Realistic Assumptions'!$B$71/12,0) -> 145 | ... M38: =ROUND('Realistic Assumptions'!$B$71/12,0) -> 145 | O38: =SUM(B38:M38) -> 1740
A39: Total Fixed Costs | B39: =SUM(B33:B38) -> 1834 | C39: =SUM(C33:C38) -> 1834 | D39: =SUM(D33:D38) -> 1834 | E39: =SUM(E33:E38) -> 1834 | F39: =SUM(F33:F38) -> 1834 | G39: =SUM(G33:G38) -> 1834 | H39: =SUM(H33:H38) -> 1834 | I39: =SUM(I33:I38) -> 1834 | ... M39: =SUM(M33:M38) -> 1834 | O39: =SUM(B39:M39) -> 22008
A40: (marketing target: 10-15% of revenue, modelled at 12%)
A41: Operating Profit / (Loss) | B41: =B29-B39 -> -1095.32 | C41: =C29-C39 -> -751.25 | D41: =D29-D39 -> -751.25 | E41: =E29-E39 -> 282.93 | F41: =F29-F39 -> 743.1235 | G41: =G29-G39 -> 1432.2485 | H41: =H29-H39 -> 1766.872 | I41: =I29-I39 -> 2905.072 | ... M41: =M29-M39 -> 4684.514 | O41: =SUM(B41:M41) -> 19882.215
A42: Cumulative Operating Profit | B42: =SUM($B$41:B41) -> -1095.32 | C42: =SUM($B$41:C41) -> -1846.57 | D42: =SUM($B$41:D41) -> -2597.82 | E42: =SUM($B$41:E41) -> -2314.89 | F42: =SUM($B$41:F41) -> -1571.7665 | G42: =SUM($B$41:G41) -> -139.518 | H42: =SUM($B$41:H41) -> 1627.354 | I42: =SUM($B$41:I41) -> 4532.426 | ... M42: =SUM($B$41:M41) -> 19882.215 | O42: =SUM(B42:M42) -> 50702.71

Sheet Realistic P&L
A1: Eisla — Realistic Case: 3-Year Annual P&L
B3: Year 1 2026/27 | C3: Year 2 2027/28 | D3: Year 3 2028/29 | E3: Y1→Y2 Growth | F3: Y2→Y3 Growth
A5: VOLUME
A6: Total jobs | B6: ='Realistic Y1 Monthly'!O5 -> 155 | C6: ='Realistic Assumptions'!$B$47 -> 600 | D6: ='Realistic Assumptions'!$B$48 -> 1800 | E6: =IFERROR((C6-B6)/ABS(B6),"-") -> 2.8709677 | F6: =IFERROR((D6-C6)/ABS(C6),"-") -> 2
A7: New design jobs | B7: ='Realistic Y1 Monthly'!O7 -> 145 | C7: =ROUND(C6*(1-'Realistic Assumptions'!$B$50),0) -> 558 | D7: =ROUND(D6*(1-'Realistic Assumptions'!$B$51),0) -> 1674 | E7: =IFERROR((C7-B7)/ABS(B7),"-") -> 2.8482759 | F7: =IFERROR((D7-C7)/ABS(C7),"-") -> 2
A8: of which: standard (£599) | B8: ='Realistic Y1 Monthly'!O11 -> 96 | C8: =C7-C9-C10 -> 390 | D8: =D7-D9-D10 -> 1088 | E8: =IFERROR((C8-B8)/ABS(B8),"-") -> 3.0625 | F8: =IFERROR((D8-C8)/ABS(C8),"-") -> 1.7897436
A9: of which: promotional (£299) | B9: ='Realistic Y1 Monthly'!O9 -> 29 | C9: =ROUND(C7*'Realistic Assumptions'!$B$12,0) -> 28 | D9: =0 -> 0 | E9: =IFERROR((C9-B9)/ABS(B9),"-") -> -0.034482759 | F9: =IFERROR((D9-C9)/ABS(C9),"-") -> -1
A10: of which: repeat customer (£539) | B10: ='Realistic Y1 Monthly'!O10 -> 20 | C10: =ROUND(C7*'Realistic Assumptions'!$B$53,0) -> 140 | D10: =ROUND(D7*'Realistic Assumptions'!$B$54,0) -> 586 | E10: =IFERROR((C10-B10)/ABS(B10),"-") -> 6 | F10: =IFERROR((D10-C10)/ABS(C10),"-") -> 3.1857143
A11: Rush jobs | B11: ='Realistic Y1 Monthly'!O8 -> 14 | C11: =ROUND(C7*'Realistic Assumptions'!$B$56,0) -> 67 | D11: =ROUND(D7*'Realistic Assumptions'!$B$57,0) -> 251 | E11: =IFERROR((C11-B11)/ABS(B11),"-") -> 3.7857143 | F11: =IFERROR((D11-C11)/ABS(C11),"-") -> 2.7462687
A12: Reorder jobs | B12: ='Realistic Y1 Monthly'!O6 -> 10 | C12: =ROUND(C6*'Realistic Assumptions'!$B$50,0) -> 42 | D12: =ROUND(D6*'Realistic Assumptions'!$B$51,0) -> 126 | E12: =IFERROR((C12-B12)/ABS(B12),"-") -> 3.2 | F12: =IFERROR((D12-C12)/ABS(C12),"-") -> 2
A14: REVENUE (£)
A15: Design fee revenue | B15: ='Realistic Y1 Monthly'!O14 -> 76957 | C15: =ROUND(C8*'Realistic Assumptions'!$B$5+C9*'Realistic Assumptions'!$B$6+C10*'Realistic Assumptions'!$B$7,0) -> 317456 | D15: =ROUND(D8*'Realistic Assumptions'!$B$5+D10*'Realistic Assumptions'!$B$7,0) -> 967625 | E15: =IFERROR((C15-B15)/ABS(B15),"-") -> 3.1251088 | F15: =IFERROR((D15-C15)/ABS(C15),"-") -> 2.0480602
A16: Manufacturing — standard | B16: ='Realistic Y1 Monthly'!O15 -> 29213 | C16: =(C7-C11)*ROUND('Realistic Assumptions'!$B$30/(1-'Realistic Assumptions'!$B$9),0) -> 109493 | D16: =(D7-D11)*ROUND('Realistic Assumptions'!$B$30/(1-'Realistic Assumptions'!$B$9),0) -> 317329 | E16: =IFERROR((C16-B16)/ABS(B16),"-") -> 2.7480916 | F16: =IFERROR((D16-C16)/ABS(C16),"-") -> 1.898167
A17: Manufacturing — rush | B17: ='Realistic Y1 Monthly'!O16 -> 4970 | C17: =C11*ROUND(('Realistic Assumptions'!$B$30+'Realistic Assumptions'!$B$31)/(1-'Realistic Assumptions'!$B$9)*(1+'Realistic Assumptions'!$B$13),0) -> 23785 | D17: =D11*ROUND(('Realistic Assumptions'!$B$30+'Realistic Assumptions'!$B$31)/(1-'Realistic Assumptions'!$B$9)*(1+'Realistic Assumptions'!$B$13),0) -> 89105 | E17: =IFERROR((C17-B17)/ABS(B17),"-") -> 3.7857143 | F17: =IFERROR((D17-C17)/ABS(C17),"-") -> 2.7462687
A18: Reorder revenue | B18: ='Realistic Y1 Monthly'!O17 -> 1900 | C18: =C12*ROUND('Realistic Assumptions'!$B$30/(1-'Realistic Assumptions'!$B$10),0) -> 7980 | D18: =D12*ROUND('Realistic Assumptions'!$B$30/(1-'Realistic Assumptions'!$B$10),0) -> 23940 | E18: =IFERROR((C18-B18)/ABS(B18),"-") -> 3.2 | F18: =IFERROR((D18-C18)/ABS(C18),"-") -> 2
A19: Revision fees | B19: ='Realistic Y1 Monthly'!O18 -> 79 | C19: =ROUND(C6*'Realistic Assumptions'!$B$58*'Realistic Assumptions'!$B$14,0) -> 300 | D19: =ROUND(D6*'Realistic Assumptions'!$B$58*'Realistic Assumptions'!$B$14,0) -> 900 | E19: =IFERROR((C19-B19)/ABS(B19),"-") -> 2.7974684 | F19: =IFERROR((D19-C19)/ABS(C19),"-") -> 2
A20: Total Revenue | B20: =SUM(B15:B19) -> 113119 | C20: =SUM(C15:C19) -> 459014 | D20: =SUM(D15:D19) -> 1398899 | E20: =IFERROR((C20-B20)/ABS(B20),"-") -> 3.0577975 | F20: =IFERROR((D20-C20)/ABS(C20),"-") -> 2.0476173
A22: VARIABLE COSTS (£)
A23: PCBA cost | B23: ='Realistic Y1 Monthly'!O22 -> 25939 | C23: =C6*'Realistic Assumptions'!$B$30+C11*'Realistic Assumptions'!$B$31 -> 100742 | D23: =D6*'Realistic Assumptions'!$B$30+D11*'Realistic Assumptions'!$B$31 -> 303526 | E23: =IFERROR((C23-B23)/ABS(B23),"-") -> 2.8838043 | F23: =IFERROR((D23-C23)/ABS(C23),"-") -> 2.0129043
A24: Engineer design review | B24: ='Realistic Y1 Monthly'!O23 -> 43065 | C24: 0 | D24: 0 | E24: =IFERROR((C24-B24)/ABS(B24),"-") -> -1 | F24: =IFERROR((D24-C24)/ABS(C24),"-") -> -
A25: Claude API | B25: ='Realistic Y1 Monthly'!O24 -> 290 | C25: =C7*'Realistic Assumptions'!$B$27 -> 1116 | D25: =D7*'Realistic Assumptions'!$B$27 -> 3348 | E25: =IFERROR((C25-B25)/ABS(B25),"-") -> 2.8482759 | F25: =IFERROR((D25-C25)/ABS(C25),"-") -> 2
A26: Compute / routing | B26: ='Realistic Y1 Monthly'!O25 -> 145 | C26: =C7*'Realistic Assumptions'!$B$28 -> 558 | D26: =D7*'Realistic Assumptions'!$B$28 -> 1674 | E26: =IFERROR((C26-B26)/ABS(B26),"-") -> 2.8482759 | F26: =IFERROR((D26-C26)/ABS(C26),"-") -> 2
A27: DigiKey API | B27: ='Realistic Y1 Monthly'!O26 -> 0 | C27: =C7*'Realistic Assumptions'!$B$29 -> 0 | D27: =D7*'Realistic Assumptions'!$B$29 -> 0 | E27: =IFERROR((C27-B27)/ABS(B27),"-") -> - | F27: =IFERROR((D27-C27)/ABS(C27),"-") -> -
A28: Stripe fees | B28: ='Realistic Y1 Monthly'!O27 -> 1789.785 | C28: =C20*'Realistic Assumptions'!$B$32+C6*2*'Realistic Assumptions'!$B$33 -> 7245.21 | D28: =D20*'Realistic Assumptions'!$B$32+D6*2*'Realistic Assumptions'!$B$33 -> 22063.485 | E28: =IFERROR((C28-B28)/ABS(B28),"-") -> 3.0480896 | F28: =IFERROR((D28-C28)/ABS(C28),"-") -> 2.0452513
A29: Total Variable Costs | B29: =SUM(B23:B28) -> 71228.785 | C29: =SUM(C23:C28) -> 109661.21 | D29: =SUM(D23:D28) -> 330611.48 | E29: =IFERROR((C29-B29)/ABS(B29),"-") -> 0.53956311 | F29: =IFERROR((D29-C29)/ABS(C29),"-") -> 2.0148444
A30: Gross Profit | B30: =B20-B29 -> 41890.215 | C30: =C20-C29 -> 349352.79 | D30: =D20-D29 -> 1068287.5 | E30: =IFERROR((C30-B30)/ABS(B30),"-") -> 7.339723 | F30: =IFERROR((D30-C30)/ABS(C30),"-") -> 2.0579046
A31: Gross Margin % | B31: =IFERROR(B30/B20,0) -> 0.37031988 | C31: =IFERROR(C30/C20,0) -> 0.76109398 | D31: =IFERROR(D30/D20,0) -> 0.76366308 | E31: =IFERROR((C31-B31)/ABS(B31),"-") -> 1.0552339 | F31: =IFERROR((D31-C31)/ABS(C31),"-") -> 0.0033755383
A33: FIXED COSTS (£)
A34: Hosting | B34: ='Realistic Assumptions'!$B$61 -> 1800 | C34: ='Realistic Assumptions'!$B$62 -> 3600 | D34: ='Realistic Assumptions'!$B$63 -> 6000
A35: Domain, IT & data | B35: 1160 | C35: 1410 | D35: 1810
A36: Accountancy & legal | B36: ='Realistic Assumptions'!$B$66 -> 3300 | C36: 1700 | D36: 2500
A37: Insurance (PI) | B37: ='Realistic Assumptions'!$B$67 -> 500 | C37: ='Realistic Assumptions'!$B$67 -> 500 | D37: ='Realistic Assumptions'!$B$67+200 -> 700
A38: Marketing (12% of revenue) | B38: ='Realistic Assumptions'!$B$68 -> 13500 | C38: ='Realistic Assumptions'!$B$69 -> 55000 | D38: ='Realistic Assumptions'!$B$70 -> 168000
A39: Full-time engineers (loaded cost) | B39: 0 | C39: 88750 | D39: 263750
A40: Total Fixed Costs | B40: =SUM(B34:B39)+'Realistic Assumptions'!$B$71 -> 22000 | C40: =SUM(C34:C39)+'Realistic Assumptions'!$B$71 -> 152700 | D40: =SUM(D34:D39)+'Realistic Assumptions'!$B$71+260 -> 444760
A41: (incl. home office £1,740/yr. FT eng loaded: salary+NI+pension+CPD+IT+setup)
A42: Operating Profit | B42: =B30-B40 -> 19890.215 | C42: =C30-C40 -> 196652.79 | D42: =D30-D40 -> 623527.52 | E42: =IFERROR((C42-B42)/ABS(B42),"-") -> 8.8869112 | F42: =IFERROR((D42-C42)/ABS(C42),"-") -> 2.1707026
A43: Operating Margin % | B43: =IFERROR(B42/B20,0) -> 0.17583443 | C43: =IFERROR(C42/C20,0) -> 0.42842438 | D43: =IFERROR(D42/D20,0) -> 0.44572733
A45: KEY METRICS
A46: Avg revenue per new design job | B46: =IFERROR(B20/B7,0) -> 780.13103 | C46: =IFERROR(C20/C7,0) -> 822.60573 | D46: =IFERROR(D20/D7,0) -> 835.66249 | E46: =IFERROR((C46-B46)/ABS(B46),"-") -> 0.054445597 | F46: =IFERROR((D46-C46)/ABS(C46),"-") -> 0.015872428
...

Sheet Optimistic Assumptions
A1: Eisla — Optimistic Case: Assumptions
A2: Amber = changed vs base. Pricing/costs/tiers/review rate all identical to base. Volume and repeat rate differ.
A4: PRICING
A5: Design fee — standard blended (£) | B5: 599 | D5: Blended across MCU tiers (see tier reference). T1=£499/T2=£599/T3=£749.
A6: Design fee — promotional (selected customers, £) | B6: 299 | D6: ~50% of standard. Strategic partners only. T2/T3 promo jobs still incur review cost.
A7: Design fee — repeat customer within 6 months (£) | B7: ='Optimistic Assumptions'!$B$5*(1-'Optimistic Assumptions'!$B$8) -> 539.1 | D7: Auto-calc: standard × (1 − repeat discount). Emailed code, applied at checkout.
A8: Repeat customer discount (%) | B8: 0.1 | D8: 10% off design fee only. Manufacturing always at full price.
A9: Manufacturing margin — prototype (%) | B9: 0.26 | D9: Applied to PCBA landed cost (all 4-layer).
A10: Manufacturing margin — reorder (%) | B10: 0.13 | D10: Same board reordered; no design work.
A11: Promotional mix — Year 1 (% of new design jobs) | B11: 0.2 | D11: 20% Y1 at £299 promo rate.
A12: Promotional mix — Year 2 (% of new design jobs) | B12: 0.05 | D12: 5% Y2; 0% Y3.
A13: Rush surcharge (%) | B13: 0.375 | D13: +37.5% on customer manufacturing price.
A14: Revision fee — 2nd+ revision (£) | B14: 5 | D14: First revision always free.
A16: MCU TIER REFERENCE (no BGA — leaded/QFN only)
A17: Adjust tier fees and mix % to update blended standard fee in B5 and blended review cost in B38.
A18: Tier 1 fee (£) | B18: 499 | D18: ATmega, STM32F0/F1/F3, basic ESP8266. LQFP≤64, DIP, SOIC.
A19: Tier 1 job mix (%) | B19: 0.25 | D19: 25% of jobs
A20: Tier 2 fee (£) | B20: 599 | D20: ESP32, RP2040, nRF52840, STM32F4/F7 LQFP, QFN. Dominant tier.
A21: Tier 2 job mix (%) | B21: 0.6 | D21: 60% of jobs
A22: Tier 3 fee (£) | B22: 749 | D22: STM32H7 LQFP176/208, i.MX RT LQFP. Complex multi-peripheral. No BGA ever.
A23: Tier 3 job mix (%) | B23: 0.15 | D23: 15% of jobs
A24: Blended standard fee — CHECK vs B5 (£) | B24: ='Optimistic Assumptions'!$B$18*'Optimistic Assumptions'!$B$19+'Optimistic Assumptions'!$B$20*'Optimistic Assumptions'!$B$21+'Optimistic Assumptions'!$B$22*'Optimistic Assumptions'!$B$23 -> 596.5 | D24: Should match B5. If tiers change, update B5.
A26: AVERAGE JOB COSTS (variable, per new design job)
A27: Claude API cost per design job (£) | B27: 2 | D27: 3–5 API calls at Sonnet 4 rates
A28: Compute / FreeRouting per job (£) | B28: 1 | D28: Server time for routing + 3D render
A29: DigiKey API lookups per job (£) | B29: 0 | D29: DigiKey API deferred to v2. £0 in v1.
A30: Average PCBA landed cost — 5 boards (£) | B30: 165 | D30: JLCPCB 4-layer. Range £140–£200.
A31: PCBA landed cost — rush premium (£) | B31: 26 | D31: JLCPCB 48hr uplift (~16% of base)
A32: Stripe fee rate (%) | B32: 0.015 | D32: 1.5% per transaction
A33: Stripe fixed fee per transaction (£) | B33: 0.3 | D33: £0.30 per charge
A34: ENGINEER DESIGN REVIEW (variable cost — T2 and T3 only)
A35: T1 designs: no review (simple, automated output sufficient). T2/T3: mandatory review before Gerbers released to fab.
A36: Engineer hourly rate (£) | B36: 90 | D36: Contract electronics engineer. Day rate ~£720.
A37: Tier 1 review hours | B37: 0 | D37: No review — simple routing, single supply, standard packages
A38: Tier 2 review hours | B38: 4 | D38: 4 hours — ESP32/RP2040/nRF52840/STM32F4 complexity
A39: Tier 3 review hours | B39: 6 | D39: 6 hours — STM32H7/i.MX RT, complex multi-peripheral
A40: Tier 1 review cost (£) | B40: ='Optimistic Assumptions'!$B$37*'Optimistic Assumptions'!$B$36 -> 0 | D40: Auto-calc: T1 hours × rate
A41: Tier 2 review cost (£) | B41: ='Optimistic Assumptions'!$B$38*'Optimistic Assumptions'!$B$36 -> 360 | D41: Auto-calc: 4h × £90 = £360
A42: Tier 3 review cost (£) | B42: ='Optimistic Assumptions'!$B$39*'Optimistic Assumptions'!$B$36 -> 540 | D42: Auto-calc: 6h × £90 = £540
A43: Blended review cost per new design job (£) | B43: ='Optimistic Assumptions'!$B$19*'Optimistic Assumptions'!$B$40+'Optimistic Assumptions'!$B$21*'Optimistic Assumptions'!$B$41+'Optimistic Assumptions'!$B$23*'Optimistic Assumptions'!$B$42 -> 297 | D43: Weighted: 25%×£0 + 60%×£360 + 15%×£540 = £297. Applies to standard, repeat, AND promotional new design jobs.
...

Sheet Optimistic P&L
A1: Eisla — Optimistic Case: 3-Year P&L
B3: Year 1 2026/27 | C3: Year 2 2027/28 | D3: Year 3 2028/29 | E3: vs Base Year 1 | F3: vs Base Year 3
A5: VOLUME
A6: Total jobs | B6: ='Optimistic Assumptions'!$B$46 -> 280 | C6: ='Optimistic Assumptions'!$B$47 -> 1100 | D6: ='Optimistic Assumptions'!$B$48 -> 3600 | E6: =IFERROR((B6-'Realistic P&L'!B6)/ABS('Realistic P&L'!B6),"-") -> 0.80645161 | F6: =IFERROR((D6-'Realistic P&L'!D6)/ABS('Realistic P&L'!D6),"-") -> 1
A7: New design jobs | B7: =ROUND(B6*(1-'Optimistic Assumptions'!$B$49),0) -> 260 | C7: =ROUND(C6*(1-'Optimistic Assumptions'!$B$50),0) -> 1023 | D7: =ROUND(D6*(1-'Optimistic Assumptions'!$B$51),0) -> 3348 | E7: =IFERROR((B7-'Realistic P&L'!B7)/ABS('Realistic P&L'!B7),"-") -> 0.79310345 | F7: =IFERROR((D7-'Realistic P&L'!D7)/ABS('Realistic P&L'!D7),"-") -> 1
A8: of which: standard (£599) | B8: =B7-B9-B10 -> 143 | C8: =C7-C9-C10 -> 512 | D8: =D7-D9-D10 -> 1339 | E8: =IFERROR((B8-'Realistic P&L'!B8)/ABS('Realistic P&L'!B8),"-") -> 0.48958333 | F8: =IFERROR((D8-'Realistic P&L'!D8)/ABS('Realistic P&L'!D8),"-") -> 0.23069853
A9: of which: promotional (£299) | B9: =ROUND(B7*'Optimistic Assumptions'!$B$11,0) -> 52 | C9: =ROUND(C7*'Optimistic Assumptions'!$B$12,0) -> 51 | D9: =0 -> 0 | E9: =IFERROR((B9-'Realistic P&L'!B9)/ABS('Realistic P&L'!B9),"-") -> 0.79310345 | F9: =IFERROR((D9-'Realistic P&L'!D9)/ABS('Realistic P&L'!D9),"-") -> -
A10: of which: repeat customer (£539) | B10: =ROUND(B7*'Optimistic Assumptions'!$B$52,0) -> 65 | C10: =ROUND(C7*'Optimistic Assumptions'!$B$53,0) -> 460 | D10: =ROUND(D7*'Optimistic Assumptions'!$B$54,0) -> 2009 | E10: =IFERROR((B10-'Realistic P&L'!B10)/ABS('Realistic P&L'!B10),"-") -> 2.25 | F10: =IFERROR((D10-'Realistic P&L'!D10)/ABS('Realistic P&L'!D10),"-") -> 2.4283276
A11: Rush jobs | B11: =ROUND(B7*'Optimistic Assumptions'!$B$55,0) -> 26 | C11: =ROUND(C7*'Optimistic Assumptions'!$B$56,0) -> 153 | D11: =ROUND(D7*'Optimistic Assumptions'!$B$57,0) -> 603 | E11: =IFERROR((B11-'Realistic P&L'!B11)/ABS('Realistic P&L'!B11),"-") -> 0.85714286 | F11: =IFERROR((D11-'Realistic P&L'!D11)/ABS('Realistic P&L'!D11),"-") -> 1.4023904
A12: Reorder jobs | B12: =ROUND(B6*'Optimistic Assumptions'!$B$49,0) -> 20 | C12: =ROUND(C6*'Optimistic Assumptions'!$B$50,0) -> 77 | D12: =ROUND(D6*'Optimistic Assumptions'!$B$51,0) -> 252 | E12: =IFERROR((B12-'Realistic P&L'!B12)/ABS('Realistic P&L'!B12),"-") -> 1 | F12: =IFERROR((D12-'Realistic P&L'!D12)/ABS('Realistic P&L'!D12),"-") -> 1
A14: REVENUE (£)
A15: Design fee revenue | B15: =ROUND(B8*'Optimistic Assumptions'!$B$5+B9*'Optimistic Assumptions'!$B$6+B10*'Optimistic Assumptions'!$B$7,0) -> 136247 | C15: =ROUND(C8*'Optimistic Assumptions'!$B$5+C9*'Optimistic Assumptions'!$B$6+C10*'Optimistic Assumptions'!$B$7,0) -> 569923 | D15: =ROUND(D8*'Optimistic Assumptions'!$B$5+D10*'Optimistic Assumptions'!$B$7,0) -> 1885113 | E15: =IFERROR((B15-'Realistic P&L'!B15)/ABS('Realistic P&L'!B15),"-") -> 0.77043024 | F15: =IFERROR((D15-'Realistic P&L'!D15)/ABS('Realistic P&L'!D15),"-") -> 0.94818551
A16: Manufacturing — standard | B16: =(B7-B11)*ROUND('Optimistic Assumptions'!$B$30/(1-'Optimistic Assumptions'!$B$9),0) -> 52182 | C16: =(C7-C11)*ROUND('Optimistic Assumptions'!$B$30/(1-'Optimistic Assumptions'!$B$9),0) -> 194010 | D16: =(D7-D11)*ROUND('Optimistic Assumptions'!$B$30/(1-'Optimistic Assumptions'!$B$9),0) -> 612135 | E16: =IFERROR((B16-'Realistic P&L'!B16)/ABS('Realistic P&L'!B16),"-") -> 0.78625954 | F16: =IFERROR((D16-'Realistic P&L'!D16)/ABS('Realistic P&L'!D16),"-") -> 0.92902319
A17: Manufacturing — rush | B17: =B11*ROUND(('Optimistic Assumptions'!$B$30+'Optimistic Assumptions'!$B$31)/(1-'Optimistic Assumptions'!$B$9)*(1+'Optimistic Assumptions'!$B$13),0) -> 9230 | C17: =C11*ROUND(('Optimistic Assumptions'!$B$30+'Optimistic Assumptions'!$B$31)/(1-'Optimistic Assumptions'!$B$9)*(1+'Optimistic Assumptions'!$B$13),0) -> 54315 | D17: =D11*ROUND(('Optimistic Assumptions'!$B$30+'Optimistic Assumptions'!$B$31)/(1-'Optimistic Assumptions'!$B$9)*(1+'Optimistic Assumptions'!$B$13),0) -> 214065 | E17: =IFERROR((B17-'Realistic P&L'!B17)/ABS('Realistic P&L'!B17),"-") -> 0.85714286 | F17: =IFERROR((D17-'Realistic P&L'!D17)/ABS('Realistic P&L'!D17),"-") -> 1.4023904
A18: Reorder revenue | B18: =B12*ROUND('Optimistic Assumptions'!$B$30/(1-'Optimistic Assumptions'!$B$10),0) -> 3800 | C18: =C12*ROUND('Optimistic Assumptions'!$B$30/(1-'Optimistic Assumptions'!$B$10),0) -> 14630 | D18: =D12*ROUND('Optimistic Assumptions'!$B$30/(1-'Optimistic Assumptions'!$B$10),0) -> 47880 | E18: =IFERROR((B18-'Realistic P&L'!B18)/ABS('Realistic P&L'!B18),"-") -> 1 | F18: =IFERROR((D18-'Realistic P&L'!D18)/ABS('Realistic P&L'!D18),"-") -> 1
A19: Revision fees | B19: =ROUND(B6*'Optimistic Assumptions'!$B$58*'Optimistic Assumptions'!$B$14,0) -> 140 | C19: =ROUND(C6*'Optimistic Assumptions'!$B$58*'Optimistic Assumptions'!$B$14,0) -> 550 | D19: =ROUND(D6*'Optimistic Assumptions'!$B$58*'Optimistic Assumptions'!$B$14,0) -> 1800 | E19: =IFERROR((B19-'Realistic P&L'!B19)/ABS('Realistic P&L'!B19),"-") -> 0.7721519 | F19: =IFERROR((D19-'Realistic P&L'!D19)/ABS('Realistic P&L'!D19),"-") -> 1
A20: Total Revenue | B20: =SUM(B15:B19) -> 201599 | C20: =SUM(C15:C19) -> 833428 | D20: =SUM(D15:D19) -> 2760993 | E20: =IFERROR((B20-'Realistic P&L'!B20)/ABS('Realistic P&L'!B20),"-") -> 0.78218513 | F20: =IFERROR((D20-'Realistic P&L'!D20)/ABS('Realistic P&L'!D20),"-") -> 0.97369002
A22: VARIABLE COSTS (£)
A23: PCBA cost | B23: =B6*'Optimistic Assumptions'!$B$30+B11*'Optimistic Assumptions'!$B$31 -> 46876 | C23: =C6*'Optimistic Assumptions'!$B$30+C11*'Optimistic Assumptions'!$B$31 -> 185478 | D23: =D6*'Optimistic Assumptions'!$B$30+D11*'Optimistic Assumptions'!$B$31 -> 609678 | E23: =IFERROR((B23-'Realistic P&L'!B23)/ABS('Realistic P&L'!B23),"-") -> 0.80716296 | F23: =IFERROR((D23-'Realistic P&L'!D23)/ABS('Realistic P&L'!D23),"-") -> 1.0086516
A24: Engineer design review | B24: 0 | C24: 0 | D24: 0 | E24: =IFERROR((B24-'Realistic P&L'!B24)/ABS('Realistic P&L'!B24),"-") -> -1 | F24: =IFERROR((D24-'Realistic P&L'!D24)/ABS('Realistic P&L'!D24),"-") -> -
A25: Claude API | B25: =B7*'Optimistic Assumptions'!$B$27 -> 520 | C25: =C7*'Optimistic Assumptions'!$B$27 -> 2046 | D25: =D7*'Optimistic Assumptions'!$B$27 -> 6696 | E25: =IFERROR((B25-'Realistic P&L'!B25)/ABS('Realistic P&L'!B25),"-") -> 0.79310345 | F25: =IFERROR((D25-'Realistic P&L'!D25)/ABS('Realistic P&L'!D25),"-") -> 1
A26: Compute / routing | B26: =B7*'Optimistic Assumptions'!$B$28 -> 260 | C26: =C7*'Optimistic Assumptions'!$B$28 -> 1023 | D26: =D7*'Optimistic Assumptions'!$B$28 -> 3348 | E26: =IFERROR((B26-'Realistic P&L'!B26)/ABS('Realistic P&L'!B26),"-") -> 0.79310345 | F26: =IFERROR((D26-'Realistic P&L'!D26)/ABS('Realistic P&L'!D26),"-") -> 1
A27: DigiKey API | B27: =B7*'Optimistic Assumptions'!$B$29 -> 0 | C27: =C7*'Optimistic Assumptions'!$B$29 -> 0 | D27: =D7*'Optimistic Assumptions'!$B$29 -> 0 | E27: =IFERROR((B27-'Realistic P&L'!B27)/ABS('Realistic P&L'!B27),"-") -> - | F27: =IFERROR((D27-'Realistic P&L'!D27)/ABS('Realistic P&L'!D27),"-") -> -
A28: Stripe fees | B28: =B20*'Optimistic Assumptions'!$B$32+B6*2*'Optimistic Assumptions'!$B$33 -> 3191.985 | C28: =C20*'Optimistic Assumptions'!$B$32+C6*2*'Optimistic Assumptions'!$B$33 -> 13161.42 | D28: =D20*'Optimistic Assumptions'!$B$32+D6*2*'Optimistic Assumptions'!$B$33 -> 43574.895 | E28: =IFERROR((B28-'Realistic P&L'!B28)/ABS('Realistic P&L'!B28),"-") -> 0.78344606 | F28: =IFERROR((D28-'Realistic P&L'!D28)/ABS('Realistic P&L'!D28),"-") -> 0.97497789
A29: Total Variable Costs | B29: =SUM(B23:B28) -> 50847.985 | C29: =SUM(C23:C28) -> 201708.42 | D29: =SUM(D23:D28) -> 663296.9 | E29: =IFERROR((B29-'Realistic P&L'!B29)/ABS('Realistic P&L'!B29),"-") -> -0.28613151 | F29: =IFERROR((D29-'Realistic P&L'!D29)/ABS('Realistic P&L'!D29),"-") -> 1.006273
A30: Gross Profit | B30: =B20-B29 -> 150751.02 | C30: =C20-C29 -> 631719.58 | D30: =D20-D29 -> 2097696.1 | E30: =IFERROR((B30-'Realistic P&L'!B30)/ABS('Realistic P&L'!B30),"-") -> 2.5987167 | F30: =IFERROR((D30-'Realistic P&L'!D30)/ABS('Realistic P&L'!D30),"-") -> 0.96360631
A31: Gross Margin % | B31: =IFERROR(B30/B20,0) -> 0.7477766 | C31: =IFERROR(C30/C20,0) -> 0.75797739 | D31: =IFERROR(D30/D20,0) -> 0.75976147 | E31: =IFERROR((B31-'Realistic P&L'!B31)/ABS('Realistic P&L'!B31),"-") -> 1.0192721 | F31: =IFERROR((D31-'Realistic P&L'!D31)/ABS('Realistic P&L'!D31),"-") -> -0.0051090666
A33: FIXED COSTS (£)
A34: Hosting | B34: ='Optimistic Assumptions'!$B$61 -> 1800 | C34: ='Optimistic Assumptions'!$B$62 -> 4800 | D34: ='Optimistic Assumptions'!$B$63 -> 10000 | E34: =IFERROR((B34-'Realistic P&L'!B34)/ABS('Realistic P&L'!B34),"-") -> 0 | F34: =IFERROR((D34-'Realistic P&L'!D34)/ABS('Realistic P&L'!D34),"-") -> 0.66666667
A35: Domain, IT & data | B35: 1310 | C35: 1510 | D35: 2160 | E35: =IFERROR((B35-'Realistic P&L'!B35)/ABS('Realistic P&L'!B35),"-") -> 0.12931034 | F35: =IFERROR((D35-'Realistic P&L'!D35)/ABS('Realistic P&L'!D35),"-") -> 0.19337017
A36: Accountancy & legal | B36: ='Optimistic Assumptions'!$B$66 -> 3300 | C36: 1700 | D36: 2500 | E36: =IFERROR((B36-'Realistic P&L'!B36)/ABS('Realistic P&L'!B36),"-") -> 0 | F36: =IFERROR((D36-'Realistic P&L'!D36)/ABS('Realistic P&L'!D36),"-") -> 0
A37: Insurance (PI) | B37: ='Optimistic Assumptions'!$B$69 -> 500 | C37: ='Optimistic Assumptions'!$B$69 -> 500 | D37: ='Optimistic Assumptions'!$B$69+200 -> 700 | E37: =IFERROR((B37-'Realistic P&L'!B37)/ABS('Realistic P&L'!B37),"-") -> 0 | F37: =IFERROR((D37-'Realistic P&L'!D37)/ABS('Realistic P&L'!D37),"-") -> 0
A38: Marketing (12% of revenue) | B38: ='Optimistic Assumptions'!$B$70 -> 24000 | C38: ='Optimistic Assumptions'!$B$71 -> 100000 | D38: ='Optimistic Assumptions'!$B$72 -> 331500 | E38: =IFERROR((B38-'Realistic P&L'!B38)/ABS('Realistic P&L'!B38),"-") -> 0.77777778 | F38: =IFERROR((D38-'Realistic P&L'!D38)/ABS('Realistic P&L'!D38),"-") -> 0.97321429
A39: Part-time support (Y2) | B39: 0 | C39: ='Optimistic Assumptions'!$B$67 -> 6000 | D39: 0 | E39: =IFERROR((B37-'Realistic P&L'!B37)/ABS('Realistic P&L'!B37),"-") -> 0 | F39: =IFERROR((D37-'Realistic P&L'!D37)/ABS('Realistic P&L'!D37),"-") -> 0
